[2024-06-25T09:05:39.138+0000] {local_task_job_runner.py:120} INFO - ::group::Pre task execution logs
[2024-06-25T09:05:39.208+0000] {taskinstance.py:2076} INFO - Dependencies all met for dep_context=non-requeueable deps ti=<TaskInstance: dbt_snowflake_v6.dbt_to_postgres scheduled__2024-06-24T00:00:00+00:00 [queued]>
[2024-06-25T09:05:39.228+0000] {taskinstance.py:2076} INFO - Dependencies all met for dep_context=requeueable deps ti=<TaskInstance: dbt_snowflake_v6.dbt_to_postgres scheduled__2024-06-24T00:00:00+00:00 [queued]>
[2024-06-25T09:05:39.229+0000] {taskinstance.py:2306} INFO - Starting attempt 1 of 2
[2024-06-25T09:05:39.257+0000] {taskinstance.py:2330} INFO - Executing <Task(DockerOperator): dbt_to_postgres> on 2024-06-24 00:00:00+00:00
[2024-06-25T09:05:39.270+0000] {standard_task_runner.py:90} INFO - Running: ['***', 'tasks', 'run', 'dbt_snowflake_v6', 'dbt_to_postgres', 'scheduled__2024-06-24T00:00:00+00:00', '--job-id', '31', '--raw', '--subdir', 'DAGS_FOLDER/first_dag.py', '--cfg-path', '/tmp/tmpjhow8hn2']
[2024-06-25T09:05:39.275+0000] {standard_task_runner.py:91} INFO - Job 31: Subtask dbt_to_postgres
[2024-06-25T09:05:39.285+0000] {logging_mixin.py:188} WARNING - /home/***/.local/lib/python3.12/site-packages/***/task/task_runner/standard_task_runner.py:61 DeprecationWarning: This process (pid=1669) is multi-threaded, use of fork() may lead to deadlocks in the child.
[2024-06-25T09:05:39.287+0000] {standard_task_runner.py:63} INFO - Started process 1670 to run task
[2024-06-25T09:05:39.391+0000] {task_command.py:426} INFO - Running <TaskInstance: dbt_snowflake_v6.dbt_to_postgres scheduled__2024-06-24T00:00:00+00:00 [running]> on host 40877dbc4b09
[2024-06-25T09:05:39.545+0000] {taskinstance.py:2648} INFO - Exporting env vars: AIRFLOW_CTX_DAG_OWNER='***' AIRFLOW_CTX_DAG_ID='dbt_snowflake_v6' AIRFLOW_CTX_TASK_ID='dbt_to_postgres' AIRFLOW_CTX_EXECUTION_DATE='2024-06-24T00:00:00+00:00' AIRFLOW_CTX_TRY_NUMBER='1' AIRFLOW_CTX_DAG_RUN_ID='scheduled__2024-06-24T00:00:00+00:00'
[2024-06-25T09:05:39.546+0000] {taskinstance.py:430} INFO - ::endgroup::
[2024-06-25T09:05:39.598+0000] {docker.py:366} INFO - Starting docker container from image ghcr.io/dbt-labs/dbt-postgres:latest
[2024-06-25T09:05:39.602+0000] {docker.py:374} WARNING - Using remote engine or docker-in-docker and mounting temporary volume from host is not supported. Falling back to `mount_tmp_dir=False` mode. You can set `mount_tmp_dir` parameter to False to disable mounting and remove the warning
[2024-06-25T09:05:44.334+0000] {docker.py:436} INFO - [0m09:05:44  Running with dbt=1.8.3
[2024-06-25T09:05:44.786+0000] {docker.py:436} INFO - [0m09:05:44  Registered adapter: postgres=1.8.2
[2024-06-25T09:05:45.069+0000] {docker.py:436} INFO - [0m09:05:45  Unable to do partial parsing because of a version mismatch
[2024-06-25T09:05:47.964+0000] {docker.py:436} INFO - [0m09:05:47  [[33mWARNING[0m]: Deprecated functionality
The `tests` config has been renamed to `data_tests`. Please see
https://docs.getdbt.com/docs/build/data-tests#new-data_tests-syntax for more
information.
[2024-06-25T09:05:48.551+0000] {docker.py:436} INFO - [0m09:05:48  Found 5 models, 9 data tests, 2 sources, 532 macros
[2024-06-25T09:05:48.559+0000] {docker.py:436} INFO - [0m09:05:48
[2024-06-25T09:05:49.029+0000] {docker.py:436} INFO - [0m09:05:49
[2024-06-25T09:05:49.030+0000] {docker.py:436} INFO - [0m09:05:49  Finished running  in 0 hours 0 minutes and 0.47 seconds (0.47s).
[2024-06-25T09:05:49.032+0000] {docker.py:436} INFO - [0m09:05:49  Encountered an error:
Database Error
  could not translate host name "host.docker.internal" to address: Name or service not known
[2024-06-25T09:05:51.442+0000] {taskinstance.py:441} INFO - ::group::Post task execution logs
[2024-06-25T09:05:51.461+0000] {taskinstance.py:2905} ERROR - Task failed with exception
Traceback (most recent call last):
  File "/home/airflow/.local/lib/python3.12/site-packages/docker/api/client.py", line 275, in _raise_for_status
    response.raise_for_status()
  File "/home/airflow/.local/lib/python3.12/site-packages/requests/models.py", line 1021, in raise_for_status
    raise HTTPError(http_error_msg, response=self)
requests.exceptions.HTTPError: 400 Client Error: Bad Request for url: http://docker-proxy:2375/v1.43/containers/create

The above exception was the direct cause of the following exception:

Traceback (most recent call last):
  File "/home/airflow/.local/lib/python3.12/site-packages/airflow/providers/docker/operators/docker.py", line 371, in _run_image
    return self._run_image_with_mounts([*self.mounts, tmp_mount], add_tmp_variable=True)
           ^^^^^^^^^^^^^^^^^^^^^^^^^^^^^^^^^^^^^^^^^^^^^^^^^^^^^^^^^^^^^^^^^^^^^^^^^^^^^
  File "/home/airflow/.local/lib/python3.12/site-packages/airflow/providers/docker/operators/docker.py", line 398, in _run_image_with_mounts
    self.container = self.cli.create_container(
                     ^^^^^^^^^^^^^^^^^^^^^^^^^^
  File "/home/airflow/.local/lib/python3.12/site-packages/docker/api/container.py", line 440, in create_container
    return self.create_container_from_config(config, name, platform)
           ^^^^^^^^^^^^^^^^^^^^^^^^^^^^^^^^^^^^^^^^^^^^^^^^^^^^^^^^^
  File "/home/airflow/.local/lib/python3.12/site-packages/docker/api/container.py", line 457, in create_container_from_config
    return self._result(res, True)
           ^^^^^^^^^^^^^^^^^^^^^^^
  File "/home/airflow/.local/lib/python3.12/site-packages/docker/api/client.py", line 281, in _result
    self._raise_for_status(response)
  File "/home/airflow/.local/lib/python3.12/site-packages/docker/api/client.py", line 277, in _raise_for_status
    raise create_api_error_from_http_exception(e) from e
          ^^^^^^^^^^^^^^^^^^^^^^^^^^^^^^^^^^^^^^^
  File "/home/airflow/.local/lib/python3.12/site-packages/docker/errors.py", line 39, in create_api_error_from_http_exception
    raise cls(e, response=response, explanation=explanation) from e
docker.errors.APIError: 400 Client Error for http://docker-proxy:2375/v1.43/containers/create: Bad Request ("invalid mount config for type "bind": bind source path does not exist: /tmp/airflowtmp1mhwly9o")

During handling of the above exception, another exception occurred:

Traceback (most recent call last):
  File "/home/airflow/.local/lib/python3.12/site-packages/airflow/models/taskinstance.py", line 465, in _execute_task
    result = _execute_callable(context=context, **execute_callable_kwargs)
             ^^^^^^^^^^^^^^^^^^^^^^^^^^^^^^^^^^^^^^^^^^^^^^^^^^^^^^^^^^^^^
  File "/home/airflow/.local/lib/python3.12/site-packages/airflow/models/taskinstance.py", line 432, in _execute_callable
    return execute_callable(context=context, **execute_callable_kwargs)
           ^^^^^^^^^^^^^^^^^^^^^^^^^^^^^^^^^^^^^^^^^^^^^^^^^^^^^^^^^^^^
  File "/home/airflow/.local/lib/python3.12/site-packages/airflow/models/baseoperator.py", line 401, in wrapper
    return func(self, *args, **kwargs)
           ^^^^^^^^^^^^^^^^^^^^^^^^^^^
  File "/home/airflow/.local/lib/python3.12/site-packages/airflow/providers/docker/operators/docker.py", line 509, in execute
    return self._run_image()
           ^^^^^^^^^^^^^^^^^
  File "/home/airflow/.local/lib/python3.12/site-packages/airflow/providers/docker/operators/docker.py", line 380, in _run_image
    return self._run_image_with_mounts(self.mounts, add_tmp_variable=False)
           ^^^^^^^^^^^^^^^^^^^^^^^^^^^^^^^^^^^^^^^^^^^^^^^^^^^^^^^^^^^^^^^^
  File "/home/airflow/.local/lib/python3.12/site-packages/airflow/providers/docker/operators/docker.py", line 444, in _run_image_with_mounts
    raise DockerContainerFailedException(f"Docker container failed: {result!r}", logs=log_lines)
airflow.providers.docker.exceptions.DockerContainerFailedException: Docker container failed: {'StatusCode': 2}
[2024-06-25T09:05:51.476+0000] {taskinstance.py:1206} INFO - Marking task as UP_FOR_RETRY. dag_id=dbt_snowflake_v6, task_id=dbt_to_postgres, run_id=scheduled__2024-06-24T00:00:00+00:00, execution_date=20240624T000000, start_date=20240625T090539, end_date=20240625T090551
[2024-06-25T09:05:51.499+0000] {standard_task_runner.py:110} ERROR - Failed to execute job 31 for task dbt_to_postgres (Docker container failed: {'StatusCode': 2}; 1670)
[2024-06-25T09:05:51.552+0000] {local_task_job_runner.py:240} INFO - Task exited with return code 1
[2024-06-25T09:05:51.580+0000] {taskinstance.py:3503} INFO - 0 downstream tasks scheduled from follow-on schedule check
[2024-06-25T09:05:51.584+0000] {local_task_job_runner.py:222} INFO - ::endgroup::
