[2024-06-25T08:41:14.040+0000] {local_task_job_runner.py:120} INFO - ::group::Pre task execution logs
[2024-06-25T08:41:14.097+0000] {taskinstance.py:2076} INFO - Dependencies all met for dep_context=non-requeueable deps ti=<TaskInstance: dbt_snowflake_v5.dbt_to_postgres scheduled__2024-06-24T00:00:00+00:00 [queued]>
[2024-06-25T08:41:14.115+0000] {taskinstance.py:2076} INFO - Dependencies all met for dep_context=requeueable deps ti=<TaskInstance: dbt_snowflake_v5.dbt_to_postgres scheduled__2024-06-24T00:00:00+00:00 [queued]>
[2024-06-25T08:41:14.116+0000] {taskinstance.py:2306} INFO - Starting attempt 1 of 2
[2024-06-25T08:41:14.165+0000] {taskinstance.py:2330} INFO - Executing <Task(DockerOperator): dbt_to_postgres> on 2024-06-24 00:00:00+00:00
[2024-06-25T08:41:14.178+0000] {standard_task_runner.py:90} INFO - Running: ['***', 'tasks', 'run', 'dbt_snowflake_v5', 'dbt_to_postgres', 'scheduled__2024-06-24T00:00:00+00:00', '--job-id', '12', '--raw', '--subdir', 'DAGS_FOLDER/first_dag.py', '--cfg-path', '/tmp/tmpofzd3pla']
[2024-06-25T08:41:14.183+0000] {standard_task_runner.py:91} INFO - Job 12: Subtask dbt_to_postgres
[2024-06-25T08:41:14.187+0000] {logging_mixin.py:188} WARNING - /home/***/.local/lib/python3.12/site-packages/***/task/task_runner/standard_task_runner.py:61 DeprecationWarning: This process (pid=1019) is multi-threaded, use of fork() may lead to deadlocks in the child.
[2024-06-25T08:41:14.187+0000] {standard_task_runner.py:63} INFO - Started process 1020 to run task
[2024-06-25T08:41:14.252+0000] {task_command.py:426} INFO - Running <TaskInstance: dbt_snowflake_v5.dbt_to_postgres scheduled__2024-06-24T00:00:00+00:00 [running]> on host 40877dbc4b09
[2024-06-25T08:41:14.379+0000] {taskinstance.py:2648} INFO - Exporting env vars: AIRFLOW_CTX_DAG_OWNER='***' AIRFLOW_CTX_DAG_ID='dbt_snowflake_v5' AIRFLOW_CTX_TASK_ID='dbt_to_postgres' AIRFLOW_CTX_EXECUTION_DATE='2024-06-24T00:00:00+00:00' AIRFLOW_CTX_TRY_NUMBER='1' AIRFLOW_CTX_DAG_RUN_ID='scheduled__2024-06-24T00:00:00+00:00'
[2024-06-25T08:41:14.381+0000] {taskinstance.py:430} INFO - ::endgroup::
[2024-06-25T08:41:14.435+0000] {docker.py:493} INFO - Pulling docker image fishtownanalytics/dbt:latest
[2024-06-25T08:41:17.591+0000] {taskinstance.py:441} INFO - ::group::Post task execution logs
[2024-06-25T08:41:17.592+0000] {taskinstance.py:2905} ERROR - Task failed with exception
Traceback (most recent call last):
  File "/home/airflow/.local/lib/python3.12/site-packages/docker/api/client.py", line 275, in _raise_for_status
    response.raise_for_status()
  File "/home/airflow/.local/lib/python3.12/site-packages/requests/models.py", line 1021, in raise_for_status
    raise HTTPError(http_error_msg, response=self)
requests.exceptions.HTTPError: 404 Client Error: Not Found for url: http://docker-proxy:2375/v1.43/images/create?tag=latest&fromImage=fishtownanalytics%2Fdbt

The above exception was the direct cause of the following exception:

Traceback (most recent call last):
  File "/home/airflow/.local/lib/python3.12/site-packages/airflow/models/taskinstance.py", line 465, in _execute_task
    result = _execute_callable(context=context, **execute_callable_kwargs)
             ^^^^^^^^^^^^^^^^^^^^^^^^^^^^^^^^^^^^^^^^^^^^^^^^^^^^^^^^^^^^^
  File "/home/airflow/.local/lib/python3.12/site-packages/airflow/models/taskinstance.py", line 432, in _execute_callable
    return execute_callable(context=context, **execute_callable_kwargs)
           ^^^^^^^^^^^^^^^^^^^^^^^^^^^^^^^^^^^^^^^^^^^^^^^^^^^^^^^^^^^^
  File "/home/airflow/.local/lib/python3.12/site-packages/airflow/models/baseoperator.py", line 401, in wrapper
    return func(self, *args, **kwargs)
           ^^^^^^^^^^^^^^^^^^^^^^^^^^^
  File "/home/airflow/.local/lib/python3.12/site-packages/airflow/providers/docker/operators/docker.py", line 495, in execute
    for output in self.cli.pull(self.image, stream=True, decode=True):
                  ^^^^^^^^^^^^^^^^^^^^^^^^^^^^^^^^^^^^^^^^^^^^^^^^^^^
  File "/home/airflow/.local/lib/python3.12/site-packages/docker/api/image.py", line 429, in pull
    self._raise_for_status(response)
  File "/home/airflow/.local/lib/python3.12/site-packages/docker/api/client.py", line 277, in _raise_for_status
    raise create_api_error_from_http_exception(e) from e
          ^^^^^^^^^^^^^^^^^^^^^^^^^^^^^^^^^^^^^^^
  File "/home/airflow/.local/lib/python3.12/site-packages/docker/errors.py", line 39, in create_api_error_from_http_exception
    raise cls(e, response=response, explanation=explanation) from e
docker.errors.NotFound: 404 Client Error for http://docker-proxy:2375/v1.43/images/create?tag=latest&fromImage=fishtownanalytics%2Fdbt: Not Found ("manifest for fishtownanalytics/dbt:latest not found: manifest unknown: manifest unknown")
[2024-06-25T08:41:17.606+0000] {taskinstance.py:1206} INFO - Marking task as UP_FOR_RETRY. dag_id=dbt_snowflake_v5, task_id=dbt_to_postgres, run_id=scheduled__2024-06-24T00:00:00+00:00, execution_date=20240624T000000, start_date=20240625T084114, end_date=20240625T084117
[2024-06-25T08:41:17.628+0000] {standard_task_runner.py:110} ERROR - Failed to execute job 12 for task dbt_to_postgres (404 Client Error for http://docker-proxy:2375/v1.43/images/create?tag=latest&fromImage=fishtownanalytics%2Fdbt: Not Found ("manifest for fishtownanalytics/dbt:latest not found: manifest unknown: manifest unknown"); 1020)
[2024-06-25T08:41:17.654+0000] {local_task_job_runner.py:240} INFO - Task exited with return code 1
[2024-06-25T08:41:17.688+0000] {taskinstance.py:3503} INFO - 0 downstream tasks scheduled from follow-on schedule check
[2024-06-25T08:41:17.691+0000] {local_task_job_runner.py:222} INFO - ::endgroup::
