[2024-06-26T09:20:22.051+0000] {local_task_job_runner.py:120} INFO - ::group::Pre task execution logs
[2024-06-26T09:20:22.115+0000] {taskinstance.py:2076} INFO - Dependencies all met for dep_context=non-requeueable deps ti=<TaskInstance: elt_and_dbt.dbt_run manual__2024-06-26T09:20:18.217893+00:00 [queued]>
[2024-06-26T09:20:22.131+0000] {taskinstance.py:2076} INFO - Dependencies all met for dep_context=requeueable deps ti=<TaskInstance: elt_and_dbt.dbt_run manual__2024-06-26T09:20:18.217893+00:00 [queued]>
[2024-06-26T09:20:22.131+0000] {taskinstance.py:2306} INFO - Starting attempt 1 of 1
[2024-06-26T09:20:22.153+0000] {taskinstance.py:2330} INFO - Executing <Task(DockerOperator): dbt_run> on 2024-06-26 09:20:18.217893+00:00
[2024-06-26T09:20:22.166+0000] {standard_task_runner.py:90} INFO - Running: ['***', 'tasks', 'run', 'elt_and_dbt', 'dbt_run', 'manual__2024-06-26T09:20:18.217893+00:00', '--job-id', '4', '--raw', '--subdir', 'DAGS_FOLDER/first_dag.py', '--cfg-path', '/tmp/tmp7pcw607z']
[2024-06-26T09:20:22.169+0000] {standard_task_runner.py:91} INFO - Job 4: Subtask dbt_run
[2024-06-26T09:20:22.172+0000] {logging_mixin.py:188} WARNING - /home/***/.local/lib/python3.12/site-packages/***/task/task_runner/standard_task_runner.py:61 DeprecationWarning: This process (pid=189) is multi-threaded, use of fork() may lead to deadlocks in the child.
[2024-06-26T09:20:22.173+0000] {standard_task_runner.py:63} INFO - Started process 190 to run task
[2024-06-26T09:20:22.302+0000] {task_command.py:426} INFO - Running <TaskInstance: elt_and_dbt.dbt_run manual__2024-06-26T09:20:18.217893+00:00 [running]> on host f389e3185d73
[2024-06-26T09:20:22.540+0000] {taskinstance.py:2648} INFO - Exporting env vars: AIRFLOW_CTX_DAG_OWNER='***' AIRFLOW_CTX_DAG_ID='elt_and_dbt' AIRFLOW_CTX_TASK_ID='dbt_run' AIRFLOW_CTX_EXECUTION_DATE='2024-06-26T09:20:18.217893+00:00' AIRFLOW_CTX_TRY_NUMBER='1' AIRFLOW_CTX_DAG_RUN_ID='manual__2024-06-26T09:20:18.217893+00:00'
[2024-06-26T09:20:22.541+0000] {taskinstance.py:430} INFO - ::endgroup::
[2024-06-26T09:20:22.586+0000] {docker.py:493} INFO - Pulling docker image ghcr.io/dbt-labs/dbt-postgres:latest
[2024-06-26T09:20:24.523+0000] {docker.py:507} INFO - latest: Pulling from dbt-labs/dbt-postgres
[2024-06-26T09:20:24.885+0000] {docker.py:507} INFO - f1f26f570256: Pulling fs layer
[2024-06-26T09:20:24.886+0000] {docker.py:507} INFO - 2d2b01660885: Pulling fs layer
[2024-06-26T09:20:24.886+0000] {docker.py:507} INFO - e4e8e4c0b0e1: Pulling fs layer
[2024-06-26T09:20:24.886+0000] {docker.py:507} INFO - 1ba60f086308: Pulling fs layer
[2024-06-26T09:20:24.887+0000] {docker.py:507} INFO - 3c2fccf90be1: Pulling fs layer
[2024-06-26T09:20:24.887+0000] {docker.py:507} INFO - b2bb82ac258e: Pulling fs layer
[2024-06-26T09:20:24.888+0000] {docker.py:507} INFO - e315c1b0dd92: Pulling fs layer
[2024-06-26T09:20:24.888+0000] {docker.py:507} INFO - a666411385ee: Pulling fs layer
[2024-06-26T09:20:24.889+0000] {docker.py:507} INFO - b2f954007d57: Pulling fs layer
[2024-06-26T09:20:24.889+0000] {docker.py:507} INFO - 1ba60f086308: Waiting
[2024-06-26T09:20:24.890+0000] {docker.py:507} INFO - 3c2fccf90be1: Waiting
[2024-06-26T09:20:24.890+0000] {docker.py:507} INFO - b2bb82ac258e: Waiting
[2024-06-26T09:20:24.891+0000] {docker.py:507} INFO - e315c1b0dd92: Waiting
[2024-06-26T09:20:24.891+0000] {docker.py:507} INFO - a666411385ee: Waiting
[2024-06-26T09:20:24.892+0000] {docker.py:507} INFO - b2f954007d57: Waiting
[2024-06-26T09:20:25.570+0000] {docker.py:507} INFO - 2d2b01660885: Downloading
[2024-06-26T09:20:25.593+0000] {docker.py:507} INFO - e4e8e4c0b0e1: Downloading
[2024-06-26T09:20:25.673+0000] {docker.py:507} INFO - f1f26f570256: Downloading
[2024-06-26T09:20:25.886+0000] {docker.py:507} INFO - 2d2b01660885: Verifying Checksum
[2024-06-26T09:20:25.887+0000] {docker.py:507} INFO - 2d2b01660885: Download complete
[2024-06-26T09:20:26.065+0000] {docker.py:507} INFO - e4e8e4c0b0e1: Verifying Checksum
[2024-06-26T09:20:26.065+0000] {docker.py:507} INFO - e4e8e4c0b0e1: Download complete
[2024-06-26T09:20:26.567+0000] {docker.py:507} INFO - 1ba60f086308: Downloading
[2024-06-26T09:20:26.567+0000] {docker.py:507} INFO - 1ba60f086308: Verifying Checksum
[2024-06-26T09:20:26.568+0000] {docker.py:507} INFO - 1ba60f086308: Download complete
[2024-06-26T09:20:26.717+0000] {docker.py:507} INFO - 3c2fccf90be1: Downloading
[2024-06-26T09:20:27.093+0000] {docker.py:507} INFO - 3c2fccf90be1: Verifying Checksum
[2024-06-26T09:20:27.094+0000] {docker.py:507} INFO - 3c2fccf90be1: Download complete
[2024-06-26T09:20:27.116+0000] {docker.py:507} INFO - f1f26f570256: Verifying Checksum
[2024-06-26T09:20:27.117+0000] {docker.py:507} INFO - f1f26f570256: Download complete
[2024-06-26T09:20:27.314+0000] {docker.py:507} INFO - f1f26f570256: Extracting
[2024-06-26T09:20:27.447+0000] {docker.py:507} INFO - b2bb82ac258e: Downloading
[2024-06-26T09:20:27.918+0000] {docker.py:507} INFO - a666411385ee: Downloading
[2024-06-26T09:20:27.919+0000] {docker.py:507} INFO - a666411385ee: Verifying Checksum
[2024-06-26T09:20:27.920+0000] {docker.py:507} INFO - a666411385ee: Download complete
[2024-06-26T09:20:27.943+0000] {docker.py:507} INFO - e315c1b0dd92: Downloading
[2024-06-26T09:20:28.442+0000] {docker.py:507} INFO - e315c1b0dd92: Verifying Checksum
[2024-06-26T09:20:28.443+0000] {docker.py:507} INFO - e315c1b0dd92: Download complete
[2024-06-26T09:20:28.851+0000] {docker.py:507} INFO - b2f954007d57: Downloading
[2024-06-26T09:20:31.548+0000] {docker.py:507} INFO - b2f954007d57: Verifying Checksum
[2024-06-26T09:20:31.549+0000] {docker.py:507} INFO - b2f954007d57: Download complete
[2024-06-26T09:20:32.327+0000] {docker.py:507} INFO - f1f26f570256: Pull complete
[2024-06-26T09:20:32.344+0000] {docker.py:507} INFO - 2d2b01660885: Extracting
[2024-06-26T09:20:32.651+0000] {docker.py:507} INFO - 2d2b01660885: Pull complete
[2024-06-26T09:20:32.669+0000] {docker.py:507} INFO - e4e8e4c0b0e1: Extracting
[2024-06-26T09:20:34.726+0000] {docker.py:507} INFO - e4e8e4c0b0e1: Pull complete
[2024-06-26T09:20:34.733+0000] {docker.py:507} INFO - b2bb82ac258e: Download complete
[2024-06-26T09:20:34.737+0000] {docker.py:507} INFO - 1ba60f086308: Extracting
[2024-06-26T09:20:34.767+0000] {docker.py:507} INFO - 1ba60f086308: Pull complete
[2024-06-26T09:20:34.778+0000] {docker.py:507} INFO - 3c2fccf90be1: Extracting
[2024-06-26T09:20:35.155+0000] {docker.py:507} INFO - 3c2fccf90be1: Pull complete
[2024-06-26T09:20:35.183+0000] {docker.py:507} INFO - b2bb82ac258e: Extracting
[2024-06-26T09:20:48.000+0000] {docker.py:507} INFO - b2bb82ac258e: Pull complete
[2024-06-26T09:20:48.014+0000] {docker.py:507} INFO - e315c1b0dd92: Extracting
[2024-06-26T09:20:49.164+0000] {docker.py:507} INFO - e315c1b0dd92: Pull complete
[2024-06-26T09:20:49.173+0000] {docker.py:507} INFO - a666411385ee: Extracting
[2024-06-26T09:20:49.206+0000] {docker.py:507} INFO - a666411385ee: Pull complete
[2024-06-26T09:20:49.232+0000] {docker.py:507} INFO - b2f954007d57: Extracting
[2024-06-26T09:20:53.054+0000] {docker.py:507} INFO - b2f954007d57: Pull complete
[2024-06-26T09:20:53.158+0000] {docker.py:502} INFO - Digest: sha256:8069ed1264a8e4c3305ea9a5a14246a0bbfe02146beedafe9c39209f75d93a07
[2024-06-26T09:20:53.176+0000] {docker.py:502} INFO - Status: Downloaded newer image for ghcr.io/dbt-labs/dbt-postgres:latest
[2024-06-26T09:20:53.184+0000] {docker.py:366} INFO - Starting docker container from image ghcr.io/dbt-labs/dbt-postgres:latest
[2024-06-26T09:20:53.251+0000] {docker.py:374} WARNING - Using remote engine or docker-in-docker and mounting temporary volume from host is not supported. Falling back to `mount_tmp_dir=False` mode. You can set `mount_tmp_dir` parameter to False to disable mounting and remove the warning
[2024-06-26T09:20:59.454+0000] {docker.py:436} INFO - Usage: dbt run [OPTIONS]
Try 'dbt run -h' for help.
[2024-06-26T09:20:59.454+0000] {docker.py:436} INFO - Error: Invalid value for '--project-dir': Path '/dbt' does not exist.
[2024-06-26T09:21:00.091+0000] {taskinstance.py:441} INFO - ::group::Post task execution logs
[2024-06-26T09:21:00.104+0000] {taskinstance.py:2905} ERROR - Task failed with exception
Traceback (most recent call last):
  File "/home/airflow/.local/lib/python3.12/site-packages/docker/api/client.py", line 275, in _raise_for_status
    response.raise_for_status()
  File "/home/airflow/.local/lib/python3.12/site-packages/requests/models.py", line 1021, in raise_for_status
    raise HTTPError(http_error_msg, response=self)
requests.exceptions.HTTPError: 400 Client Error: Bad Request for url: http://docker-proxy:2375/v1.43/containers/create

The above exception was the direct cause of the following exception:

Traceback (most recent call last):
  File "/home/airflow/.local/lib/python3.12/site-packages/airflow/providers/docker/operators/docker.py", line 371, in _run_image
    return self._run_image_with_mounts([*self.mounts, tmp_mount], add_tmp_variable=True)
           ^^^^^^^^^^^^^^^^^^^^^^^^^^^^^^^^^^^^^^^^^^^^^^^^^^^^^^^^^^^^^^^^^^^^^^^^^^^^^
  File "/home/airflow/.local/lib/python3.12/site-packages/airflow/providers/docker/operators/docker.py", line 398, in _run_image_with_mounts
    self.container = self.cli.create_container(
                     ^^^^^^^^^^^^^^^^^^^^^^^^^^
  File "/home/airflow/.local/lib/python3.12/site-packages/docker/api/container.py", line 440, in create_container
    return self.create_container_from_config(config, name, platform)
           ^^^^^^^^^^^^^^^^^^^^^^^^^^^^^^^^^^^^^^^^^^^^^^^^^^^^^^^^^
  File "/home/airflow/.local/lib/python3.12/site-packages/docker/api/container.py", line 457, in create_container_from_config
    return self._result(res, True)
           ^^^^^^^^^^^^^^^^^^^^^^^
  File "/home/airflow/.local/lib/python3.12/site-packages/docker/api/client.py", line 281, in _result
    self._raise_for_status(response)
  File "/home/airflow/.local/lib/python3.12/site-packages/docker/api/client.py", line 277, in _raise_for_status
    raise create_api_error_from_http_exception(e) from e
          ^^^^^^^^^^^^^^^^^^^^^^^^^^^^^^^^^^^^^^^
  File "/home/airflow/.local/lib/python3.12/site-packages/docker/errors.py", line 39, in create_api_error_from_http_exception
    raise cls(e, response=response, explanation=explanation) from e
docker.errors.APIError: 400 Client Error for http://docker-proxy:2375/v1.43/containers/create: Bad Request ("invalid mount config for type "bind": bind source path does not exist: /tmp/airflowtmpxts6uvhi")

During handling of the above exception, another exception occurred:

Traceback (most recent call last):
  File "/home/airflow/.local/lib/python3.12/site-packages/airflow/models/taskinstance.py", line 465, in _execute_task
    result = _execute_callable(context=context, **execute_callable_kwargs)
             ^^^^^^^^^^^^^^^^^^^^^^^^^^^^^^^^^^^^^^^^^^^^^^^^^^^^^^^^^^^^^
  File "/home/airflow/.local/lib/python3.12/site-packages/airflow/models/taskinstance.py", line 432, in _execute_callable
    return execute_callable(context=context, **execute_callable_kwargs)
           ^^^^^^^^^^^^^^^^^^^^^^^^^^^^^^^^^^^^^^^^^^^^^^^^^^^^^^^^^^^^
  File "/home/airflow/.local/lib/python3.12/site-packages/airflow/models/baseoperator.py", line 401, in wrapper
    return func(self, *args, **kwargs)
           ^^^^^^^^^^^^^^^^^^^^^^^^^^^
  File "/home/airflow/.local/lib/python3.12/site-packages/airflow/providers/docker/operators/docker.py", line 509, in execute
    return self._run_image()
           ^^^^^^^^^^^^^^^^^
  File "/home/airflow/.local/lib/python3.12/site-packages/airflow/providers/docker/operators/docker.py", line 380, in _run_image
    return self._run_image_with_mounts(self.mounts, add_tmp_variable=False)
           ^^^^^^^^^^^^^^^^^^^^^^^^^^^^^^^^^^^^^^^^^^^^^^^^^^^^^^^^^^^^^^^^
  File "/home/airflow/.local/lib/python3.12/site-packages/airflow/providers/docker/operators/docker.py", line 444, in _run_image_with_mounts
    raise DockerContainerFailedException(f"Docker container failed: {result!r}", logs=log_lines)
airflow.providers.docker.exceptions.DockerContainerFailedException: Docker container failed: {'StatusCode': 2}
[2024-06-26T09:21:00.120+0000] {taskinstance.py:1206} INFO - Marking task as FAILED. dag_id=elt_and_dbt, task_id=dbt_run, run_id=manual__2024-06-26T09:20:18.217893+00:00, execution_date=20240626T092018, start_date=20240626T092022, end_date=20240626T092100
[2024-06-26T09:21:00.139+0000] {standard_task_runner.py:110} ERROR - Failed to execute job 4 for task dbt_run (Docker container failed: {'StatusCode': 2}; 190)
[2024-06-26T09:21:00.172+0000] {local_task_job_runner.py:240} INFO - Task exited with return code 1
[2024-06-26T09:21:00.196+0000] {taskinstance.py:3503} INFO - 0 downstream tasks scheduled from follow-on schedule check
[2024-06-26T09:21:00.199+0000] {local_task_job_runner.py:222} INFO - ::endgroup::
