[2024-06-25T09:38:50.781+0000] {local_task_job_runner.py:120} INFO - ::group::Pre task execution logs
[2024-06-25T09:38:50.853+0000] {taskinstance.py:2076} INFO - Dependencies all met for dep_context=non-requeueable deps ti=<TaskInstance: dbt_snowflake_v6.dbt_to_postgres manual__2024-06-25T09:32:45.913760+00:00 [queued]>
[2024-06-25T09:38:50.871+0000] {taskinstance.py:2076} INFO - Dependencies all met for dep_context=requeueable deps ti=<TaskInstance: dbt_snowflake_v6.dbt_to_postgres manual__2024-06-25T09:32:45.913760+00:00 [queued]>
[2024-06-25T09:38:50.871+0000] {taskinstance.py:2306} INFO - Starting attempt 2 of 2
[2024-06-25T09:38:50.895+0000] {taskinstance.py:2330} INFO - Executing <Task(DockerOperator): dbt_to_postgres> on 2024-06-25 09:32:45.913760+00:00
[2024-06-25T09:38:50.909+0000] {logging_mixin.py:188} WARNING - /home/***/.local/lib/python3.12/site-packages/***/task/task_runner/standard_task_runner.py:61 DeprecationWarning: This process (pid=2415) is multi-threaded, use of fork() may lead to deadlocks in the child.
[2024-06-25T09:38:50.911+0000] {standard_task_runner.py:63} INFO - Started process 2416 to run task
[2024-06-25T09:38:50.909+0000] {standard_task_runner.py:90} INFO - Running: ['***', 'tasks', 'run', 'dbt_snowflake_v6', 'dbt_to_postgres', 'manual__2024-06-25T09:32:45.913760+00:00', '--job-id', '37', '--raw', '--subdir', 'DAGS_FOLDER/first_dag.py', '--cfg-path', '/tmp/tmp2r398k9x']
[2024-06-25T09:38:50.913+0000] {standard_task_runner.py:91} INFO - Job 37: Subtask dbt_to_postgres
[2024-06-25T09:38:50.986+0000] {task_command.py:426} INFO - Running <TaskInstance: dbt_snowflake_v6.dbt_to_postgres manual__2024-06-25T09:32:45.913760+00:00 [running]> on host 40877dbc4b09
[2024-06-25T09:38:51.134+0000] {taskinstance.py:2648} INFO - Exporting env vars: AIRFLOW_CTX_DAG_OWNER='***' AIRFLOW_CTX_DAG_ID='dbt_snowflake_v6' AIRFLOW_CTX_TASK_ID='dbt_to_postgres' AIRFLOW_CTX_EXECUTION_DATE='2024-06-25T09:32:45.913760+00:00' AIRFLOW_CTX_TRY_NUMBER='2' AIRFLOW_CTX_DAG_RUN_ID='manual__2024-06-25T09:32:45.913760+00:00'
[2024-06-25T09:38:51.135+0000] {taskinstance.py:430} INFO - ::endgroup::
[2024-06-25T09:38:51.205+0000] {docker.py:366} INFO - Starting docker container from image ghcr.io/dbt-labs/dbt-postgres:latest
[2024-06-25T09:38:51.210+0000] {docker.py:374} WARNING - Using remote engine or docker-in-docker and mounting temporary volume from host is not supported. Falling back to `mount_tmp_dir=False` mode. You can set `mount_tmp_dir` parameter to False to disable mounting and remove the warning
[2024-06-25T09:38:53.786+0000] {docker.py:436} INFO - [0m09:38:53  Running with dbt=1.8.3
[2024-06-25T09:38:54.092+0000] {docker.py:436} INFO - [0m09:38:54  Registered adapter: postgres=1.8.2
[2024-06-25T09:38:54.640+0000] {docker.py:436} INFO - [0m09:38:54  Found 5 models, 9 data tests, 2 sources, 532 macros
[2024-06-25T09:38:54.644+0000] {docker.py:436} INFO - [0m09:38:54
[2024-06-25T09:39:14.762+0000] {docker.py:436} INFO - [0m09:39:14
[2024-06-25T09:39:14.763+0000] {docker.py:436} INFO - [0m09:39:14  Finished running  in 0 hours 0 minutes and 20.12 seconds (20.12s).
[2024-06-25T09:39:14.765+0000] {docker.py:436} INFO - [0m09:39:14  Encountered an error:
Database Error
  connection to server at "172.19.0.2", port 5432 failed: timeout expired
[2024-06-25T09:39:16.721+0000] {taskinstance.py:441} INFO - ::group::Post task execution logs
[2024-06-25T09:39:16.734+0000] {taskinstance.py:2905} ERROR - Task failed with exception
Traceback (most recent call last):
  File "/home/airflow/.local/lib/python3.12/site-packages/docker/api/client.py", line 275, in _raise_for_status
    response.raise_for_status()
  File "/home/airflow/.local/lib/python3.12/site-packages/requests/models.py", line 1021, in raise_for_status
    raise HTTPError(http_error_msg, response=self)
requests.exceptions.HTTPError: 400 Client Error: Bad Request for url: http://docker-proxy:2375/v1.43/containers/create

The above exception was the direct cause of the following exception:

Traceback (most recent call last):
  File "/home/airflow/.local/lib/python3.12/site-packages/airflow/providers/docker/operators/docker.py", line 371, in _run_image
    return self._run_image_with_mounts([*self.mounts, tmp_mount], add_tmp_variable=True)
           ^^^^^^^^^^^^^^^^^^^^^^^^^^^^^^^^^^^^^^^^^^^^^^^^^^^^^^^^^^^^^^^^^^^^^^^^^^^^^
  File "/home/airflow/.local/lib/python3.12/site-packages/airflow/providers/docker/operators/docker.py", line 398, in _run_image_with_mounts
    self.container = self.cli.create_container(
                     ^^^^^^^^^^^^^^^^^^^^^^^^^^
  File "/home/airflow/.local/lib/python3.12/site-packages/docker/api/container.py", line 440, in create_container
    return self.create_container_from_config(config, name, platform)
           ^^^^^^^^^^^^^^^^^^^^^^^^^^^^^^^^^^^^^^^^^^^^^^^^^^^^^^^^^
  File "/home/airflow/.local/lib/python3.12/site-packages/docker/api/container.py", line 457, in create_container_from_config
    return self._result(res, True)
           ^^^^^^^^^^^^^^^^^^^^^^^
  File "/home/airflow/.local/lib/python3.12/site-packages/docker/api/client.py", line 281, in _result
    self._raise_for_status(response)
  File "/home/airflow/.local/lib/python3.12/site-packages/docker/api/client.py", line 277, in _raise_for_status
    raise create_api_error_from_http_exception(e) from e
          ^^^^^^^^^^^^^^^^^^^^^^^^^^^^^^^^^^^^^^^
  File "/home/airflow/.local/lib/python3.12/site-packages/docker/errors.py", line 39, in create_api_error_from_http_exception
    raise cls(e, response=response, explanation=explanation) from e
docker.errors.APIError: 400 Client Error for http://docker-proxy:2375/v1.43/containers/create: Bad Request ("invalid mount config for type "bind": bind source path does not exist: /tmp/airflowtmptyn8g9ar")

During handling of the above exception, another exception occurred:

Traceback (most recent call last):
  File "/home/airflow/.local/lib/python3.12/site-packages/airflow/models/taskinstance.py", line 465, in _execute_task
    result = _execute_callable(context=context, **execute_callable_kwargs)
             ^^^^^^^^^^^^^^^^^^^^^^^^^^^^^^^^^^^^^^^^^^^^^^^^^^^^^^^^^^^^^
  File "/home/airflow/.local/lib/python3.12/site-packages/airflow/models/taskinstance.py", line 432, in _execute_callable
    return execute_callable(context=context, **execute_callable_kwargs)
           ^^^^^^^^^^^^^^^^^^^^^^^^^^^^^^^^^^^^^^^^^^^^^^^^^^^^^^^^^^^^
  File "/home/airflow/.local/lib/python3.12/site-packages/airflow/models/baseoperator.py", line 401, in wrapper
    return func(self, *args, **kwargs)
           ^^^^^^^^^^^^^^^^^^^^^^^^^^^
  File "/home/airflow/.local/lib/python3.12/site-packages/airflow/providers/docker/operators/docker.py", line 509, in execute
    return self._run_image()
           ^^^^^^^^^^^^^^^^^
  File "/home/airflow/.local/lib/python3.12/site-packages/airflow/providers/docker/operators/docker.py", line 380, in _run_image
    return self._run_image_with_mounts(self.mounts, add_tmp_variable=False)
           ^^^^^^^^^^^^^^^^^^^^^^^^^^^^^^^^^^^^^^^^^^^^^^^^^^^^^^^^^^^^^^^^
  File "/home/airflow/.local/lib/python3.12/site-packages/airflow/providers/docker/operators/docker.py", line 444, in _run_image_with_mounts
    raise DockerContainerFailedException(f"Docker container failed: {result!r}", logs=log_lines)
airflow.providers.docker.exceptions.DockerContainerFailedException: Docker container failed: {'StatusCode': 2}
[2024-06-25T09:39:16.744+0000] {taskinstance.py:1206} INFO - Marking task as FAILED. dag_id=dbt_snowflake_v6, task_id=dbt_to_postgres, run_id=manual__2024-06-25T09:32:45.913760+00:00, execution_date=20240625T093245, start_date=20240625T093850, end_date=20240625T093916
[2024-06-25T09:39:16.761+0000] {standard_task_runner.py:110} ERROR - Failed to execute job 37 for task dbt_to_postgres (Docker container failed: {'StatusCode': 2}; 2416)
[2024-06-25T09:39:16.784+0000] {local_task_job_runner.py:240} INFO - Task exited with return code 1
[2024-06-25T09:39:16.807+0000] {taskinstance.py:3503} INFO - 0 downstream tasks scheduled from follow-on schedule check
[2024-06-25T09:39:16.810+0000] {local_task_job_runner.py:222} INFO - ::endgroup::
