[2024-06-26T09:22:36.899+0000] {local_task_job_runner.py:120} INFO - ::group::Pre task execution logs
[2024-06-26T09:22:36.954+0000] {taskinstance.py:2076} INFO - Dependencies all met for dep_context=non-requeueable deps ti=<TaskInstance: elt_and_dbt.dbt_run manual__2024-06-26T09:22:33.557105+00:00 [queued]>
[2024-06-26T09:22:36.968+0000] {taskinstance.py:2076} INFO - Dependencies all met for dep_context=requeueable deps ti=<TaskInstance: elt_and_dbt.dbt_run manual__2024-06-26T09:22:33.557105+00:00 [queued]>
[2024-06-26T09:22:36.968+0000] {taskinstance.py:2306} INFO - Starting attempt 1 of 1
[2024-06-26T09:22:37.007+0000] {taskinstance.py:2330} INFO - Executing <Task(DockerOperator): dbt_run> on 2024-06-26 09:22:33.557105+00:00
[2024-06-26T09:22:37.019+0000] {standard_task_runner.py:90} INFO - Running: ['***', 'tasks', 'run', 'elt_and_dbt', 'dbt_run', 'manual__2024-06-26T09:22:33.557105+00:00', '--job-id', '6', '--raw', '--subdir', 'DAGS_FOLDER/first_dag.py', '--cfg-path', '/tmp/tmpwnpiq7av']
[2024-06-26T09:22:37.023+0000] {standard_task_runner.py:91} INFO - Job 6: Subtask dbt_run
[2024-06-26T09:22:37.027+0000] {logging_mixin.py:188} WARNING - /home/***/.local/lib/python3.12/site-packages/***/task/task_runner/standard_task_runner.py:61 DeprecationWarning: This process (pid=257) is multi-threaded, use of fork() may lead to deadlocks in the child.
[2024-06-26T09:22:37.028+0000] {standard_task_runner.py:63} INFO - Started process 258 to run task
[2024-06-26T09:22:37.093+0000] {task_command.py:426} INFO - Running <TaskInstance: elt_and_dbt.dbt_run manual__2024-06-26T09:22:33.557105+00:00 [running]> on host f389e3185d73
[2024-06-26T09:22:37.231+0000] {taskinstance.py:2648} INFO - Exporting env vars: AIRFLOW_CTX_DAG_OWNER='***' AIRFLOW_CTX_DAG_ID='elt_and_dbt' AIRFLOW_CTX_TASK_ID='dbt_run' AIRFLOW_CTX_EXECUTION_DATE='2024-06-26T09:22:33.557105+00:00' AIRFLOW_CTX_TRY_NUMBER='1' AIRFLOW_CTX_DAG_RUN_ID='manual__2024-06-26T09:22:33.557105+00:00'
[2024-06-26T09:22:37.232+0000] {taskinstance.py:430} INFO - ::endgroup::
[2024-06-26T09:22:37.334+0000] {docker.py:366} INFO - Starting docker container from image ghcr.io/dbt-labs/dbt-postgres:latest
[2024-06-26T09:22:37.338+0000] {docker.py:374} WARNING - Using remote engine or docker-in-docker and mounting temporary volume from host is not supported. Falling back to `mount_tmp_dir=False` mode. You can set `mount_tmp_dir` parameter to False to disable mounting and remove the warning
[2024-06-26T09:22:45.441+0000] {docker.py:436} INFO - [0m09:22:45  Running with dbt=1.8.3
[2024-06-26T09:22:45.805+0000] {docker.py:436} INFO - [0m09:22:45  Registered adapter: postgres=1.8.2
[2024-06-26T09:22:45.915+0000] {docker.py:436} INFO - [0m09:22:45  Unable to do partial parsing because of a version mismatch
[2024-06-26T09:22:47.901+0000] {docker.py:436} INFO - [0m09:22:47  [[33mWARNING[0m]: Deprecated functionality
The `tests` config has been renamed to `data_tests`. Please see
https://docs.getdbt.com/docs/build/data-tests#new-data_tests-syntax for more
information.
[2024-06-26T09:22:47.924+0000] {docker.py:436} INFO - [0m09:22:47  Encountered an error:
Parsing Error
  Invalid models config given in models/example/schema.yml @ models: {'name': 'actors', 'description': 'This table contains details about actors.', 'columns': [{'name': 'actor_id', 'description': 'Unique identifier for the actor.', 'tests': ['unique', 'not_null']}, {'name': 'name', 'description': 'First name of the actor.', 'tests': None}], 'original_file_path': 'models/example/schema.yml', 'yaml_key': 'models', 'package_name': 'activate_postgres'} - at path ['columns'][1]['tests']: None is not of type 'array'
[2024-06-26T09:22:49.719+0000] {taskinstance.py:441} INFO - ::group::Post task execution logs
[2024-06-26T09:22:49.735+0000] {taskinstance.py:2905} ERROR - Task failed with exception
Traceback (most recent call last):
  File "/home/airflow/.local/lib/python3.12/site-packages/docker/api/client.py", line 275, in _raise_for_status
    response.raise_for_status()
  File "/home/airflow/.local/lib/python3.12/site-packages/requests/models.py", line 1021, in raise_for_status
    raise HTTPError(http_error_msg, response=self)
requests.exceptions.HTTPError: 400 Client Error: Bad Request for url: http://docker-proxy:2375/v1.43/containers/create

The above exception was the direct cause of the following exception:

Traceback (most recent call last):
  File "/home/airflow/.local/lib/python3.12/site-packages/airflow/providers/docker/operators/docker.py", line 371, in _run_image
    return self._run_image_with_mounts([*self.mounts, tmp_mount], add_tmp_variable=True)
           ^^^^^^^^^^^^^^^^^^^^^^^^^^^^^^^^^^^^^^^^^^^^^^^^^^^^^^^^^^^^^^^^^^^^^^^^^^^^^
  File "/home/airflow/.local/lib/python3.12/site-packages/airflow/providers/docker/operators/docker.py", line 398, in _run_image_with_mounts
    self.container = self.cli.create_container(
                     ^^^^^^^^^^^^^^^^^^^^^^^^^^
  File "/home/airflow/.local/lib/python3.12/site-packages/docker/api/container.py", line 440, in create_container
    return self.create_container_from_config(config, name, platform)
           ^^^^^^^^^^^^^^^^^^^^^^^^^^^^^^^^^^^^^^^^^^^^^^^^^^^^^^^^^
  File "/home/airflow/.local/lib/python3.12/site-packages/docker/api/container.py", line 457, in create_container_from_config
    return self._result(res, True)
           ^^^^^^^^^^^^^^^^^^^^^^^
  File "/home/airflow/.local/lib/python3.12/site-packages/docker/api/client.py", line 281, in _result
    self._raise_for_status(response)
  File "/home/airflow/.local/lib/python3.12/site-packages/docker/api/client.py", line 277, in _raise_for_status
    raise create_api_error_from_http_exception(e) from e
          ^^^^^^^^^^^^^^^^^^^^^^^^^^^^^^^^^^^^^^^
  File "/home/airflow/.local/lib/python3.12/site-packages/docker/errors.py", line 39, in create_api_error_from_http_exception
    raise cls(e, response=response, explanation=explanation) from e
docker.errors.APIError: 400 Client Error for http://docker-proxy:2375/v1.43/containers/create: Bad Request ("invalid mount config for type "bind": bind source path does not exist: /tmp/airflowtmp0vmmt5k9")

During handling of the above exception, another exception occurred:

Traceback (most recent call last):
  File "/home/airflow/.local/lib/python3.12/site-packages/airflow/models/taskinstance.py", line 465, in _execute_task
    result = _execute_callable(context=context, **execute_callable_kwargs)
             ^^^^^^^^^^^^^^^^^^^^^^^^^^^^^^^^^^^^^^^^^^^^^^^^^^^^^^^^^^^^^
  File "/home/airflow/.local/lib/python3.12/site-packages/airflow/models/taskinstance.py", line 432, in _execute_callable
    return execute_callable(context=context, **execute_callable_kwargs)
           ^^^^^^^^^^^^^^^^^^^^^^^^^^^^^^^^^^^^^^^^^^^^^^^^^^^^^^^^^^^^
  File "/home/airflow/.local/lib/python3.12/site-packages/airflow/models/baseoperator.py", line 401, in wrapper
    return func(self, *args, **kwargs)
           ^^^^^^^^^^^^^^^^^^^^^^^^^^^
  File "/home/airflow/.local/lib/python3.12/site-packages/airflow/providers/docker/operators/docker.py", line 509, in execute
    return self._run_image()
           ^^^^^^^^^^^^^^^^^
  File "/home/airflow/.local/lib/python3.12/site-packages/airflow/providers/docker/operators/docker.py", line 380, in _run_image
    return self._run_image_with_mounts(self.mounts, add_tmp_variable=False)
           ^^^^^^^^^^^^^^^^^^^^^^^^^^^^^^^^^^^^^^^^^^^^^^^^^^^^^^^^^^^^^^^^
  File "/home/airflow/.local/lib/python3.12/site-packages/airflow/providers/docker/operators/docker.py", line 444, in _run_image_with_mounts
    raise DockerContainerFailedException(f"Docker container failed: {result!r}", logs=log_lines)
airflow.providers.docker.exceptions.DockerContainerFailedException: Docker container failed: {'StatusCode': 2}
[2024-06-26T09:22:49.773+0000] {taskinstance.py:1206} INFO - Marking task as FAILED. dag_id=elt_and_dbt, task_id=dbt_run, run_id=manual__2024-06-26T09:22:33.557105+00:00, execution_date=20240626T092233, start_date=20240626T092236, end_date=20240626T092249
[2024-06-26T09:22:49.793+0000] {standard_task_runner.py:110} ERROR - Failed to execute job 6 for task dbt_run (Docker container failed: {'StatusCode': 2}; 258)
[2024-06-26T09:22:49.824+0000] {local_task_job_runner.py:240} INFO - Task exited with return code 1
[2024-06-26T09:22:49.846+0000] {taskinstance.py:3503} INFO - 0 downstream tasks scheduled from follow-on schedule check
[2024-06-26T09:22:49.849+0000] {local_task_job_runner.py:222} INFO - ::endgroup::
