[2024-06-25T08:52:44.175+0000] {local_task_job_runner.py:120} INFO - ::group::Pre task execution logs
[2024-06-25T08:52:44.235+0000] {taskinstance.py:2076} INFO - Dependencies all met for dep_context=non-requeueable deps ti=<TaskInstance: dbt_snowflake_v5.2.dbt_to_postgres manual__2024-06-25T08:47:16.297873+00:00 [queued]>
[2024-06-25T08:52:44.249+0000] {taskinstance.py:2076} INFO - Dependencies all met for dep_context=requeueable deps ti=<TaskInstance: dbt_snowflake_v5.2.dbt_to_postgres manual__2024-06-25T08:47:16.297873+00:00 [queued]>
[2024-06-25T08:52:44.250+0000] {taskinstance.py:2306} INFO - Starting attempt 2 of 2
[2024-06-25T08:52:44.271+0000] {taskinstance.py:2330} INFO - Executing <Task(DockerOperator): dbt_to_postgres> on 2024-06-25 08:47:16.297873+00:00
[2024-06-25T08:52:44.283+0000] {standard_task_runner.py:90} INFO - Running: ['***', 'tasks', 'run', 'dbt_snowflake_v5.2', 'dbt_to_postgres', 'manual__2024-06-25T08:47:16.297873+00:00', '--job-id', '27', '--raw', '--subdir', 'DAGS_FOLDER/first_dag.py', '--cfg-path', '/tmp/tmpw3i32b4n']
[2024-06-25T08:52:44.286+0000] {standard_task_runner.py:91} INFO - Job 27: Subtask dbt_to_postgres
[2024-06-25T08:52:44.289+0000] {logging_mixin.py:188} WARNING - /home/***/.local/lib/python3.12/site-packages/***/task/task_runner/standard_task_runner.py:61 DeprecationWarning: This process (pid=1342) is multi-threaded, use of fork() may lead to deadlocks in the child.
[2024-06-25T08:52:44.290+0000] {standard_task_runner.py:63} INFO - Started process 1343 to run task
[2024-06-25T08:52:44.357+0000] {task_command.py:426} INFO - Running <TaskInstance: dbt_snowflake_v5.2.dbt_to_postgres manual__2024-06-25T08:47:16.297873+00:00 [running]> on host 40877dbc4b09
[2024-06-25T08:52:44.481+0000] {taskinstance.py:2648} INFO - Exporting env vars: AIRFLOW_CTX_DAG_OWNER='***' AIRFLOW_CTX_DAG_ID='dbt_snowflake_v5.2' AIRFLOW_CTX_TASK_ID='dbt_to_postgres' AIRFLOW_CTX_EXECUTION_DATE='2024-06-25T08:47:16.297873+00:00' AIRFLOW_CTX_TRY_NUMBER='2' AIRFLOW_CTX_DAG_RUN_ID='manual__2024-06-25T08:47:16.297873+00:00'
[2024-06-25T08:52:44.482+0000] {taskinstance.py:430} INFO - ::endgroup::
[2024-06-25T08:52:44.526+0000] {docker.py:366} INFO - Starting docker container from image ghcr.io/dbt-labs/dbt-postgres:latest
[2024-06-25T08:52:44.530+0000] {docker.py:374} WARNING - Using remote engine or docker-in-docker and mounting temporary volume from host is not supported. Falling back to `mount_tmp_dir=False` mode. You can set `mount_tmp_dir` parameter to False to disable mounting and remove the warning
[2024-06-25T08:52:47.072+0000] {docker.py:436} INFO - Usage: dbt run [OPTIONS]
Try 'dbt run -h' for help.
[2024-06-25T08:52:47.073+0000] {docker.py:436} INFO - Error: No such option: --target postgres (Possible options: --target, --target-path)
[2024-06-25T08:52:47.694+0000] {taskinstance.py:441} INFO - ::group::Post task execution logs
[2024-06-25T08:52:47.708+0000] {taskinstance.py:2905} ERROR - Task failed with exception
Traceback (most recent call last):
  File "/home/airflow/.local/lib/python3.12/site-packages/docker/api/client.py", line 275, in _raise_for_status
    response.raise_for_status()
  File "/home/airflow/.local/lib/python3.12/site-packages/requests/models.py", line 1021, in raise_for_status
    raise HTTPError(http_error_msg, response=self)
requests.exceptions.HTTPError: 400 Client Error: Bad Request for url: http://docker-proxy:2375/v1.43/containers/create

The above exception was the direct cause of the following exception:

Traceback (most recent call last):
  File "/home/airflow/.local/lib/python3.12/site-packages/airflow/providers/docker/operators/docker.py", line 371, in _run_image
    return self._run_image_with_mounts([*self.mounts, tmp_mount], add_tmp_variable=True)
           ^^^^^^^^^^^^^^^^^^^^^^^^^^^^^^^^^^^^^^^^^^^^^^^^^^^^^^^^^^^^^^^^^^^^^^^^^^^^^
  File "/home/airflow/.local/lib/python3.12/site-packages/airflow/providers/docker/operators/docker.py", line 398, in _run_image_with_mounts
    self.container = self.cli.create_container(
                     ^^^^^^^^^^^^^^^^^^^^^^^^^^
  File "/home/airflow/.local/lib/python3.12/site-packages/docker/api/container.py", line 440, in create_container
    return self.create_container_from_config(config, name, platform)
           ^^^^^^^^^^^^^^^^^^^^^^^^^^^^^^^^^^^^^^^^^^^^^^^^^^^^^^^^^
  File "/home/airflow/.local/lib/python3.12/site-packages/docker/api/container.py", line 457, in create_container_from_config
    return self._result(res, True)
           ^^^^^^^^^^^^^^^^^^^^^^^
  File "/home/airflow/.local/lib/python3.12/site-packages/docker/api/client.py", line 281, in _result
    self._raise_for_status(response)
  File "/home/airflow/.local/lib/python3.12/site-packages/docker/api/client.py", line 277, in _raise_for_status
    raise create_api_error_from_http_exception(e) from e
          ^^^^^^^^^^^^^^^^^^^^^^^^^^^^^^^^^^^^^^^
  File "/home/airflow/.local/lib/python3.12/site-packages/docker/errors.py", line 39, in create_api_error_from_http_exception
    raise cls(e, response=response, explanation=explanation) from e
docker.errors.APIError: 400 Client Error for http://docker-proxy:2375/v1.43/containers/create: Bad Request ("invalid mount config for type "bind": bind source path does not exist: /tmp/airflowtmp6twz7374")

During handling of the above exception, another exception occurred:

Traceback (most recent call last):
  File "/home/airflow/.local/lib/python3.12/site-packages/airflow/models/taskinstance.py", line 465, in _execute_task
    result = _execute_callable(context=context, **execute_callable_kwargs)
             ^^^^^^^^^^^^^^^^^^^^^^^^^^^^^^^^^^^^^^^^^^^^^^^^^^^^^^^^^^^^^
  File "/home/airflow/.local/lib/python3.12/site-packages/airflow/models/taskinstance.py", line 432, in _execute_callable
    return execute_callable(context=context, **execute_callable_kwargs)
           ^^^^^^^^^^^^^^^^^^^^^^^^^^^^^^^^^^^^^^^^^^^^^^^^^^^^^^^^^^^^
  File "/home/airflow/.local/lib/python3.12/site-packages/airflow/models/baseoperator.py", line 401, in wrapper
    return func(self, *args, **kwargs)
           ^^^^^^^^^^^^^^^^^^^^^^^^^^^
  File "/home/airflow/.local/lib/python3.12/site-packages/airflow/providers/docker/operators/docker.py", line 509, in execute
    return self._run_image()
           ^^^^^^^^^^^^^^^^^
  File "/home/airflow/.local/lib/python3.12/site-packages/airflow/providers/docker/operators/docker.py", line 380, in _run_image
    return self._run_image_with_mounts(self.mounts, add_tmp_variable=False)
           ^^^^^^^^^^^^^^^^^^^^^^^^^^^^^^^^^^^^^^^^^^^^^^^^^^^^^^^^^^^^^^^^
  File "/home/airflow/.local/lib/python3.12/site-packages/airflow/providers/docker/operators/docker.py", line 444, in _run_image_with_mounts
    raise DockerContainerFailedException(f"Docker container failed: {result!r}", logs=log_lines)
airflow.providers.docker.exceptions.DockerContainerFailedException: Docker container failed: {'StatusCode': 2}
[2024-06-25T08:52:47.718+0000] {taskinstance.py:1206} INFO - Marking task as FAILED. dag_id=dbt_snowflake_v5.2, task_id=dbt_to_postgres, run_id=manual__2024-06-25T08:47:16.297873+00:00, execution_date=20240625T084716, start_date=20240625T085244, end_date=20240625T085247
[2024-06-25T08:52:47.740+0000] {standard_task_runner.py:110} ERROR - Failed to execute job 27 for task dbt_to_postgres (Docker container failed: {'StatusCode': 2}; 1343)
[2024-06-25T08:52:47.757+0000] {local_task_job_runner.py:240} INFO - Task exited with return code 1
[2024-06-25T08:52:47.781+0000] {taskinstance.py:3503} INFO - 0 downstream tasks scheduled from follow-on schedule check
[2024-06-25T08:52:47.784+0000] {local_task_job_runner.py:222} INFO - ::endgroup::
