[2024-06-24T08:34:38.547+0000] {local_task_job_runner.py:120} INFO - ::group::Pre task execution logs
[2024-06-24T08:34:38.599+0000] {taskinstance.py:2076} INFO - Dependencies all met for dep_context=non-requeueable deps ti=<TaskInstance: docker_postgres_dag.run_postgres_container manual__2024-06-24T08:29:34.559901+00:00 [queued]>
[2024-06-24T08:34:38.613+0000] {taskinstance.py:2076} INFO - Dependencies all met for dep_context=requeueable deps ti=<TaskInstance: docker_postgres_dag.run_postgres_container manual__2024-06-24T08:29:34.559901+00:00 [queued]>
[2024-06-24T08:34:38.614+0000] {taskinstance.py:2306} INFO - Starting attempt 2 of 2
[2024-06-24T08:34:38.635+0000] {taskinstance.py:2330} INFO - Executing <Task(DockerOperator): run_postgres_container> on 2024-06-24 08:29:34.559901+00:00
[2024-06-24T08:34:38.649+0000] {standard_task_runner.py:90} INFO - Running: ['***', 'tasks', 'run', 'docker_postgres_dag', 'run_postgres_container', 'manual__2024-06-24T08:29:34.559901+00:00', '--job-id', '6', '--raw', '--subdir', 'DAGS_FOLDER/first_dag.py', '--cfg-path', '/tmp/tmpvhz62izt']
[2024-06-24T08:34:38.654+0000] {standard_task_runner.py:91} INFO - Job 6: Subtask run_postgres_container
[2024-06-24T08:34:38.656+0000] {logging_mixin.py:188} WARNING - /home/***/.local/lib/python3.12/site-packages/***/task/task_runner/standard_task_runner.py:61 DeprecationWarning: This process (pid=309) is multi-threaded, use of fork() may lead to deadlocks in the child.
[2024-06-24T08:34:38.657+0000] {standard_task_runner.py:63} INFO - Started process 312 to run task
[2024-06-24T08:34:38.776+0000] {task_command.py:426} INFO - Running <TaskInstance: docker_postgres_dag.run_postgres_container manual__2024-06-24T08:29:34.559901+00:00 [running]> on host 84721074d007
[2024-06-24T08:34:38.925+0000] {taskinstance.py:2648} INFO - Exporting env vars: AIRFLOW_CTX_DAG_OWNER='***' AIRFLOW_CTX_DAG_ID='docker_postgres_dag' AIRFLOW_CTX_TASK_ID='run_postgres_container' AIRFLOW_CTX_EXECUTION_DATE='2024-06-24T08:29:34.559901+00:00' AIRFLOW_CTX_TRY_NUMBER='2' AIRFLOW_CTX_DAG_RUN_ID='manual__2024-06-24T08:29:34.559901+00:00'
[2024-06-24T08:34:38.927+0000] {taskinstance.py:430} INFO - ::endgroup::
[2024-06-24T08:34:38.958+0000] {docker.py:157} ERROR - Failed to establish connection to Docker host unix://var/run/docker.sock: Error while fetching server API version: ('Connection aborted.', FileNotFoundError(2, 'No such file or directory'))
[2024-06-24T08:34:38.959+0000] {taskinstance.py:441} INFO - ::group::Post task execution logs
[2024-06-24T08:34:38.990+0000] {taskinstance.py:2905} ERROR - Task failed with exception
Traceback (most recent call last):
  File "/home/airflow/.local/lib/python3.12/site-packages/airflow/models/taskinstance.py", line 465, in _execute_task
    result = _execute_callable(context=context, **execute_callable_kwargs)
             ^^^^^^^^^^^^^^^^^^^^^^^^^^^^^^^^^^^^^^^^^^^^^^^^^^^^^^^^^^^^^
  File "/home/airflow/.local/lib/python3.12/site-packages/airflow/models/taskinstance.py", line 432, in _execute_callable
    return execute_callable(context=context, **execute_callable_kwargs)
           ^^^^^^^^^^^^^^^^^^^^^^^^^^^^^^^^^^^^^^^^^^^^^^^^^^^^^^^^^^^^
  File "/home/airflow/.local/lib/python3.12/site-packages/airflow/models/baseoperator.py", line 401, in wrapper
    return func(self, *args, **kwargs)
           ^^^^^^^^^^^^^^^^^^^^^^^^^^^
  File "/home/airflow/.local/lib/python3.12/site-packages/airflow/providers/docker/operators/docker.py", line 492, in execute
    if self.force_pull or not self.cli.images(name=self.image):
                              ^^^^^^^^
  File "/home/airflow/.local/lib/python3.12/site-packages/airflow/providers/docker/operators/docker.py", line 362, in cli
    return self.hook.api_client
           ^^^^^^^^^^^^^^^^^^^^
  File "/usr/local/lib/python3.12/functools.py", line 995, in __get__
    val = self.func(instance)
          ^^^^^^^^^^^^^^^^^^^
  File "/home/airflow/.local/lib/python3.12/site-packages/airflow/providers/docker/hooks/docker.py", line 161, in api_client
    raise AirflowException("Failed to establish connection to any given Docker hosts.")
airflow.exceptions.AirflowException: Failed to establish connection to any given Docker hosts.
[2024-06-24T08:34:39.000+0000] {taskinstance.py:1206} INFO - Marking task as FAILED. dag_id=docker_postgres_dag, task_id=run_postgres_container, run_id=manual__2024-06-24T08:29:34.559901+00:00, execution_date=20240624T082934, start_date=20240624T083438, end_date=20240624T083438
[2024-06-24T08:34:39.029+0000] {standard_task_runner.py:110} ERROR - Failed to execute job 6 for task run_postgres_container (Failed to establish connection to any given Docker hosts.; 312)
[2024-06-24T08:34:39.051+0000] {local_task_job_runner.py:240} INFO - Task exited with return code 1
[2024-06-24T08:34:39.077+0000] {taskinstance.py:3503} INFO - 0 downstream tasks scheduled from follow-on schedule check
[2024-06-24T08:34:39.080+0000] {local_task_job_runner.py:222} INFO - ::endgroup::
