[2024-06-24T08:00:28.376+0000] {local_task_job_runner.py:120} INFO - ::group::Pre task execution logs
[2024-06-24T08:00:28.447+0000] {taskinstance.py:2076} INFO - Dependencies all met for dep_context=non-requeueable deps ti=<TaskInstance: dbt_snowflake_v03.dbt_run manual__2024-06-24T08:00:26.663196+00:00 [queued]>
[2024-06-24T08:00:28.467+0000] {taskinstance.py:2076} INFO - Dependencies all met for dep_context=requeueable deps ti=<TaskInstance: dbt_snowflake_v03.dbt_run manual__2024-06-24T08:00:26.663196+00:00 [queued]>
[2024-06-24T08:00:28.468+0000] {taskinstance.py:2306} INFO - Starting attempt 1 of 2
[2024-06-24T08:00:28.499+0000] {taskinstance.py:2330} INFO - Executing <Task(DockerOperator): dbt_run> on 2024-06-24 08:00:26.663196+00:00
[2024-06-24T08:00:28.510+0000] {standard_task_runner.py:90} INFO - Running: ['***', 'tasks', 'run', 'dbt_snowflake_v03', 'dbt_run', 'manual__2024-06-24T08:00:26.663196+00:00', '--job-id', '7', '--raw', '--subdir', 'DAGS_FOLDER/first_dag.py', '--cfg-path', '/tmp/tmp0y228vf7']
[2024-06-24T08:00:28.514+0000] {standard_task_runner.py:91} INFO - Job 7: Subtask dbt_run
[2024-06-24T08:00:28.518+0000] {logging_mixin.py:188} WARNING - /home/***/.local/lib/python3.12/site-packages/***/task/task_runner/standard_task_runner.py:61 DeprecationWarning: This process (pid=1552) is multi-threaded, use of fork() may lead to deadlocks in the child.
[2024-06-24T08:00:28.519+0000] {standard_task_runner.py:63} INFO - Started process 1553 to run task
[2024-06-24T08:00:28.590+0000] {task_command.py:426} INFO - Running <TaskInstance: dbt_snowflake_v03.dbt_run manual__2024-06-24T08:00:26.663196+00:00 [running]> on host 8dde1c55cac5
[2024-06-24T08:00:28.782+0000] {taskinstance.py:2648} INFO - Exporting env vars: AIRFLOW_CTX_DAG_OWNER='***' AIRFLOW_CTX_DAG_ID='dbt_snowflake_v03' AIRFLOW_CTX_TASK_ID='dbt_run' AIRFLOW_CTX_EXECUTION_DATE='2024-06-24T08:00:26.663196+00:00' AIRFLOW_CTX_TRY_NUMBER='1' AIRFLOW_CTX_DAG_RUN_ID='manual__2024-06-24T08:00:26.663196+00:00'
[2024-06-24T08:00:28.783+0000] {taskinstance.py:430} INFO - ::endgroup::
[2024-06-24T08:00:28.819+0000] {docker.py:157} ERROR - Failed to establish connection to Docker host /var/run/docker.sock: Invalid bind address format: /var/run/docker.sock
[2024-06-24T08:00:28.820+0000] {taskinstance.py:441} INFO - ::group::Post task execution logs
[2024-06-24T08:00:28.833+0000] {taskinstance.py:2905} ERROR - Task failed with exception
Traceback (most recent call last):
  File "/home/airflow/.local/lib/python3.12/site-packages/airflow/models/taskinstance.py", line 465, in _execute_task
    result = _execute_callable(context=context, **execute_callable_kwargs)
             ^^^^^^^^^^^^^^^^^^^^^^^^^^^^^^^^^^^^^^^^^^^^^^^^^^^^^^^^^^^^^
  File "/home/airflow/.local/lib/python3.12/site-packages/airflow/models/taskinstance.py", line 432, in _execute_callable
    return execute_callable(context=context, **execute_callable_kwargs)
           ^^^^^^^^^^^^^^^^^^^^^^^^^^^^^^^^^^^^^^^^^^^^^^^^^^^^^^^^^^^^
  File "/home/airflow/.local/lib/python3.12/site-packages/airflow/models/baseoperator.py", line 401, in wrapper
    return func(self, *args, **kwargs)
           ^^^^^^^^^^^^^^^^^^^^^^^^^^^
  File "/home/airflow/.local/lib/python3.12/site-packages/airflow/providers/docker/operators/docker.py", line 492, in execute
    if self.force_pull or not self.cli.images(name=self.image):
                              ^^^^^^^^
  File "/home/airflow/.local/lib/python3.12/site-packages/airflow/providers/docker/operators/docker.py", line 362, in cli
    return self.hook.api_client
           ^^^^^^^^^^^^^^^^^^^^
  File "/usr/local/lib/python3.12/functools.py", line 995, in __get__
    val = self.func(instance)
          ^^^^^^^^^^^^^^^^^^^
  File "/home/airflow/.local/lib/python3.12/site-packages/airflow/providers/docker/hooks/docker.py", line 161, in api_client
    raise AirflowException("Failed to establish connection to any given Docker hosts.")
airflow.exceptions.AirflowException: Failed to establish connection to any given Docker hosts.
[2024-06-24T08:00:28.839+0000] {taskinstance.py:1206} INFO - Marking task as UP_FOR_RETRY. dag_id=dbt_snowflake_v03, task_id=dbt_run, run_id=manual__2024-06-24T08:00:26.663196+00:00, execution_date=20240624T080026, start_date=20240624T080028, end_date=20240624T080028
[2024-06-24T08:00:28.856+0000] {standard_task_runner.py:110} ERROR - Failed to execute job 7 for task dbt_run (Failed to establish connection to any given Docker hosts.; 1553)
[2024-06-24T08:00:28.897+0000] {local_task_job_runner.py:240} INFO - Task exited with return code 1
[2024-06-24T08:00:28.928+0000] {taskinstance.py:3503} INFO - 0 downstream tasks scheduled from follow-on schedule check
[2024-06-24T08:00:28.932+0000] {local_task_job_runner.py:222} INFO - ::endgroup::
