[2024-06-26T09:41:05.217+0000] {local_task_job_runner.py:120} INFO - ::group::Pre task execution logs
[2024-06-26T09:41:05.270+0000] {taskinstance.py:2076} INFO - Dependencies all met for dep_context=non-requeueable deps ti=<TaskInstance: elt_and_dbt.dbt_run manual__2024-06-26T09:41:02.394291+00:00 [queued]>
[2024-06-26T09:41:05.283+0000] {taskinstance.py:2076} INFO - Dependencies all met for dep_context=requeueable deps ti=<TaskInstance: elt_and_dbt.dbt_run manual__2024-06-26T09:41:02.394291+00:00 [queued]>
[2024-06-26T09:41:05.284+0000] {taskinstance.py:2306} INFO - Starting attempt 1 of 1
[2024-06-26T09:41:05.303+0000] {taskinstance.py:2330} INFO - Executing <Task(DockerOperator): dbt_run> on 2024-06-26 09:41:02.394291+00:00
[2024-06-26T09:41:05.315+0000] {standard_task_runner.py:90} INFO - Running: ['***', 'tasks', 'run', 'elt_and_dbt', 'dbt_run', 'manual__2024-06-26T09:41:02.394291+00:00', '--job-id', '14', '--raw', '--subdir', 'DAGS_FOLDER/first_dag.py', '--cfg-path', '/tmp/tmprk2ejwdc']
[2024-06-26T09:41:05.319+0000] {standard_task_runner.py:91} INFO - Job 14: Subtask dbt_run
[2024-06-26T09:41:05.321+0000] {logging_mixin.py:188} WARNING - /home/***/.local/lib/python3.12/site-packages/***/task/task_runner/standard_task_runner.py:61 DeprecationWarning: This process (pid=564) is multi-threaded, use of fork() may lead to deadlocks in the child.
[2024-06-26T09:41:05.322+0000] {standard_task_runner.py:63} INFO - Started process 565 to run task
[2024-06-26T09:41:05.387+0000] {task_command.py:426} INFO - Running <TaskInstance: elt_and_dbt.dbt_run manual__2024-06-26T09:41:02.394291+00:00 [running]> on host 7347636032b9
[2024-06-26T09:41:05.534+0000] {taskinstance.py:2648} INFO - Exporting env vars: AIRFLOW_CTX_DAG_OWNER='***' AIRFLOW_CTX_DAG_ID='elt_and_dbt' AIRFLOW_CTX_TASK_ID='dbt_run' AIRFLOW_CTX_EXECUTION_DATE='2024-06-26T09:41:02.394291+00:00' AIRFLOW_CTX_TRY_NUMBER='1' AIRFLOW_CTX_DAG_RUN_ID='manual__2024-06-26T09:41:02.394291+00:00'
[2024-06-26T09:41:05.536+0000] {taskinstance.py:430} INFO - ::endgroup::
[2024-06-26T09:41:05.559+0000] {docker.py:157} ERROR - Failed to establish connection to Docker host unix://var/run/docker.sock: Error while fetching server API version: ('Connection aborted.', PermissionError(13, 'Permission denied'))
[2024-06-26T09:41:05.560+0000] {taskinstance.py:441} INFO - ::group::Post task execution logs
[2024-06-26T09:41:05.574+0000] {taskinstance.py:2905} ERROR - Task failed with exception
Traceback (most recent call last):
  File "/home/airflow/.local/lib/python3.12/site-packages/airflow/models/taskinstance.py", line 465, in _execute_task
    result = _execute_callable(context=context, **execute_callable_kwargs)
             ^^^^^^^^^^^^^^^^^^^^^^^^^^^^^^^^^^^^^^^^^^^^^^^^^^^^^^^^^^^^^
  File "/home/airflow/.local/lib/python3.12/site-packages/airflow/models/taskinstance.py", line 432, in _execute_callable
    return execute_callable(context=context, **execute_callable_kwargs)
           ^^^^^^^^^^^^^^^^^^^^^^^^^^^^^^^^^^^^^^^^^^^^^^^^^^^^^^^^^^^^
  File "/home/airflow/.local/lib/python3.12/site-packages/airflow/models/baseoperator.py", line 401, in wrapper
    return func(self, *args, **kwargs)
           ^^^^^^^^^^^^^^^^^^^^^^^^^^^
  File "/home/airflow/.local/lib/python3.12/site-packages/airflow/providers/docker/operators/docker.py", line 492, in execute
    if self.force_pull or not self.cli.images(name=self.image):
                              ^^^^^^^^
  File "/home/airflow/.local/lib/python3.12/site-packages/airflow/providers/docker/operators/docker.py", line 362, in cli
    return self.hook.api_client
           ^^^^^^^^^^^^^^^^^^^^
  File "/usr/local/lib/python3.12/functools.py", line 995, in __get__
    val = self.func(instance)
          ^^^^^^^^^^^^^^^^^^^
  File "/home/airflow/.local/lib/python3.12/site-packages/airflow/providers/docker/hooks/docker.py", line 161, in api_client
    raise AirflowException("Failed to establish connection to any given Docker hosts.")
airflow.exceptions.AirflowException: Failed to establish connection to any given Docker hosts.
[2024-06-26T09:41:05.581+0000] {taskinstance.py:1206} INFO - Marking task as FAILED. dag_id=elt_and_dbt, task_id=dbt_run, run_id=manual__2024-06-26T09:41:02.394291+00:00, execution_date=20240626T094102, start_date=20240626T094105, end_date=20240626T094105
[2024-06-26T09:41:05.599+0000] {standard_task_runner.py:110} ERROR - Failed to execute job 14 for task dbt_run (Failed to establish connection to any given Docker hosts.; 565)
[2024-06-26T09:41:05.617+0000] {local_task_job_runner.py:240} INFO - Task exited with return code 1
[2024-06-26T09:41:05.641+0000] {taskinstance.py:3503} INFO - 0 downstream tasks scheduled from follow-on schedule check
[2024-06-26T09:41:05.645+0000] {local_task_job_runner.py:222} INFO - ::endgroup::
